Workbook

Sheet NFLX
A1: Date | B1: Open | C1: High | D1: Low | E1: Close | F1: Adj Close | G1: Volume
A2: 46031 | B2: 90.03 | C2: 90.05 | D2: 88.32 | E2: 89.46 | F2: 89.46 | G2: 55504000
A3: 46030 | B3: 90.45 | C3: 91.25 | D3: 89.58 | E3: 90.53 | F3: 90.53 | G3: 40068700
A4: 46029 | B4: 91.56 | C4: 92.42 | D4: 90.06 | E4: 90.73 | F4: 90.73 | G4: 36525700
A5: 46028 | B5: 91.54 | C5: 91.64 | D5: 89.74 | E5: 90.65 | F5: 90.65 | G5: 43331000
A6: 46027 | B6: 90.92 | C6: 92.63 | D6: 90.84 | E6: 91.46 | F6: 91.46 | G6: 39183300
A7: 46024 | B7: 94.13 | C7: 94.13 | D7: 90.81 | E7: 90.99 | F7: 90.99 | G7: 41155400
A8: 46022 | B8: 93.6 | C8: 94.31 | D8: 93.2 | E8: 93.76 | F8: 93.76 | G8: 23495200
A9: 46021 | B9: 93.52 | C9: 93.99 | D9: 93.34 | E9: 93.78 | F9: 93.78 | G9: 23422000
A10: 46020 | B10: 93.99 | C10: 94.97 | D10: 93.63 | E10: 94.15 | F10: 94.15 | G10: 24493700
A11: 46017 | B11: 93.48 | C11: 94.69 | D11: 93.27 | E11: 94.47 | F11: 94.47 | G11: 22068300
A12: 46015 | B12: 93.11 | C12: 93.68 | D12: 92.67 | E12: 93.64 | F12: 93.64 | G12: 12427900
A13: 46014 | B13: 93.4 | C13: 93.81 | D13: 91.33 | E13: 93.5 | F13: 93.5 | G13: 25896200
... A251: 45670 | B251: 83.15 | C251: 84.71 | D251: 82.91 | E251: 84.03 | F251: 84.03 | G251: 30245000

Sheet V
A1: Date | B1: Open | C1: High | D1: Low | E1: Close | F1: Adj Close | G1: Volume
A2: 46031 | B2: 352.16 | C2: 354.7 | D2: 349.16 | E2: 349.77 | F2: 349.77 | G2: 4902900
A3: 46030 | B3: 355 | C3: 356.35 | D3: 349.5 | E3: 352.23 | F3: 352.23 | G3: 6357600
A4: 46029 | B4: 357.15 | C4: 358.28 | D4: 354.51 | E4: 355.88 | F4: 355.88 | G4: 6333900
A5: 46028 | B5: 353.68 | C5: 358.62 | D5: 352 | E5: 357.56 | F5: 357.56 | G5: 6775400
A6: 46027 | B6: 344.5 | C6: 357.54 | D6: 344.05 | E6: 353.8 | F6: 353.8 | G6: 7592200
A7: 46024 | B7: 349.87 | C7: 350.05 | D7: 343.48 | E7: 346.48 | F7: 346.48 | G7: 5403800
A8: 46022 | B8: 353.65 | C8: 355.2 | D8: 350.69 | E8: 350.71 | F8: 350.71 | G8: 3503200
A9: 46021 | B9: 354 | C9: 354.87 | D9: 352.66 | E9: 353.62 | F9: 353.62 | G9: 3366500
A10: 46020 | B10: 355.49 | C10: 356.55 | D10: 353.8 | E10: 354.61 | F10: 354.61 | G10: 3989900
A11: 46017 | B11: 355.1 | C11: 356.73 | D11: 353.71 | E11: 355 | F11: 355 | G11: 2017000
A12: 46015 | B12: 353.38 | C12: 355.99 | D12: 353.01 | E12: 355.14 | F12: 355.14 | G12: 2023600
A13: 46014 | B13: 352 | C13: 356.38 | D13: 352 | E13: 353.38 | F13: 353.38 | G13: 3703200
... A252: 45667 | B252: 311.2 | C252: 311.85 | D252: 305.99 | E252: 307.71 | F252: 305.54 | G252: 6660100

Sheet XOM
A1: Date | B1: Open | C1: High | D1: Low | E1: Close | F1: Adj Close | G1: Volume
A2: 46031 | B2: 123.23 | C2: 124.86 | D2: 123.1 | E2: 124.61 | F2: 124.61 | G2: 16131600
A3: 46030 | B3: 118.98 | C3: 123.63 | D3: 118.66 | E3: 122.91 | F3: 122.91 | G3: 20232700
A4: 46029 | B4: 119.8 | C4: 120.12 | D4: 118.27 | E4: 118.49 | F4: 118.49 | G4: 20353000
A5: 46028 | B5: 125.35 | C5: 125.8 | D5: 121 | E5: 121.05 | F5: 121.05 | G5: 23328600
A6: 46027 | B6: 125.21 | C6: 125.93 | D6: 122.39 | E6: 125.36 | F6: 125.36 | G6: 30112200
A7: 46024 | B7: 120.09 | C7: 122.68 | D7: 119.61 | E7: 122.65 | F7: 122.65 | G7: 14715100
A8: 46022 | B8: 121.18 | C8: 121.26 | D8: 119.87 | E8: 120.34 | F8: 120.34 | G8: 10559900
A9: 46021 | B9: 121.1 | C9: 121.8 | D9: 120.63 | E9: 120.99 | F9: 120.99 | G9: 11150500
A10: 46020 | B10: 120.15 | C10: 121.3 | D10: 119.4 | E10: 120.53 | F10: 120.53 | G10: 14782500
A11: 46017 | B11: 118.89 | C11: 119.55 | D11: 118.53 | E11: 119.11 | F11: 119.11 | G11: 8066100
A12: 46015 | B12: 119.33 | C12: 120.05 | D12: 119.12 | E12: 119.22 | F12: 119.22 | G12: 6137400
A13: 46014 | B13: 118.47 | C13: 120.03 | D13: 118.32 | E13: 119.42 | F13: 119.42 | G13: 12567600
... A252: 45667 | B252: 108.7 | C252: 110.1 | D252: 105.78 | E252: 106.54 | F252: 102.77 | G252: 19304500

Sheet PFE
A1: Date | B1: Open | C1: High | D1: Low | E1: Close | F1: Adj Close | G1: Volume
A2: 46031 | B2: 25.34 | C2: 25.55 | D2: 25.23 | E2: 25.48 | F2: 25.48 | G2: 34172400
A3: 46030 | B3: 25.18 | C3: 25.56 | D3: 25.12 | E3: 25.29 | F3: 25.29 | G3: 42977300
A4: 46029 | B4: 25.59 | C4: 25.81 | D4: 25.14 | E4: 25.28 | F4: 25.28 | G4: 51395800
A5: 46028 | B5: 25.19 | C5: 26.01 | D5: 25.19 | E5: 25.43 | F5: 25.43 | G5: 50977300
A6: 46027 | B6: 25.2 | C6: 25.4 | D6: 24.95 | E6: 25.17 | F6: 25.17 | G6: 52620900
A7: 46024 | B7: 24.98 | C7: 25.3 | D7: 24.83 | E7: 25.18 | F7: 25.18 | G7: 35976700
A8: 46022 | B8: 24.97 | C8: 25.02 | D8: 24.88 | E8: 24.9 | F8: 24.9 | G8: 29409200
A9: 46021 | B9: 25.01 | C9: 25.05 | D9: 24.92 | E9: 24.99 | F9: 24.99 | G9: 28821700
A10: 46020 | B10: 25.05 | C10: 25.2 | D10: 24.97 | E10: 25 | F10: 25 | G10: 33067700
A11: 46017 | B11: 25.02 | C11: 25.11 | D11: 24.92 | E11: 25.09 | F11: 25.09 | G11: 21617800
A12: 46015 | B12: 24.92 | C12: 25.14 | D12: 24.91 | E12: 25.03 | F12: 25.03 | G12: 19328500
A13: 46014 | B13: 25.26 | C13: 25.34 | D13: 24.83 | E13: 24.88 | F13: 24.88 | G13: 43692900
... A252: 45667 | B252: 26.87 | C252: 27.05 | D252: 26.69 | E252: 26.72 | F252: 24.92 | G252: 32836900

Sheet PG
A1: Date | B1: Open | C1: High | D1: Low | E1: Close | F1: Adj Close | G1: Volume
A2: 46031 | B2: 141.7 | C2: 142.33 | D2: 140.83 | E2: 141.87 | F2: 141.87 | G2: 9522700
A3: 46030 | B3: 137.89 | C3: 141.78 | D3: 137.82 | E3: 141.53 | F3: 141.53 | G3: 9297100
A4: 46029 | B4: 139.8 | C4: 139.8 | D4: 137.62 | E4: 138.04 | F4: 138.04 | G4: 14369100
A5: 46028 | B5: 140.39 | C5: 141.42 | D5: 139.51 | E5: 139.91 | F5: 139.91 | G5: 10421800
A6: 46027 | B6: 141.1 | C6: 141.35 | D6: 139.6 | E6: 140.37 | F6: 140.37 | G6: 12297300
A7: 46024 | B7: 143.11 | C7: 143.34 | D7: 141.24 | E7: 141.79 | F7: 141.79 | G7: 8946100
A8: 46022 | B8: 144 | C8: 144.14 | D8: 143.23 | E8: 143.31 | F8: 143.31 | G8: 5293200
A9: 46021 | B9: 144.29 | C9: 144.46 | D9: 143.57 | E9: 144.05 | F9: 144.05 | G9: 6006400
A10: 46020 | B10: 144.8 | C10: 145.07 | D10: 143.95 | E10: 144.57 | F10: 144.57 | G10: 7662100
A11: 46017 | B11: 144.31 | C11: 145.64 | D11: 144.31 | E11: 144.74 | F11: 144.74 | G11: 4711500
A12: 46015 | B12: 142.9 | C12: 144.74 | D12: 142.83 | E12: 144.49 | F12: 144.49 | G12: 3259200
A13: 46014 | B13: 142.49 | C13: 143.73 | D13: 142.08 | E13: 143.18 | F13: 143.18 | G13: 9541600
... A252: 45667 | B252: 160.15 | C252: 161.21 | D252: 157.47 | E252: 158.56 | F252: 154.48 | G252: 8501500

Sheet S&P 500
A1: Date | B1: Open | C1: High | D1: Low | E1: Close | F1: Adj Close | G1: Volume
A2: 46031 | B2: 6927.83 | C2: 6978.36 | D2: 6917.64 | E2: 6966.28 | F2: 6966.28 | G2: 5163900000
A3: 46030 | B3: 6914.11 | C3: 6931.28 | D3: 6899.33 | E3: 6921.46 | F3: 6921.46 | G3: 5333200000
A4: 46029 | B4: 6945.07 | C4: 6965.69 | D4: 6919.19 | E4: 6920.93 | F4: 6920.93 | G4: 5214480000
A5: 46028 | B5: 6908.03 | C5: 6948.69 | D5: 6904.02 | E5: 6944.82 | F5: 6944.82 | G5: 5509680000
A6: 46027 | B6: 6892.19 | C6: 6920.38 | D6: 6891.56 | E6: 6902.05 | F6: 6902.05 | G6: 5771930000
A7: 46024 | B7: 6878.11 | C7: 6894.87 | D7: 6824.31 | E7: 6858.47 | F7: 6858.47 | G7: 4184120000
A8: 46022 | B8: 6898.82 | C8: 6901.42 | D8: 6844.55 | E8: 6845.5 | F8: 6845.5 | G8: 3261830000
A9: 46021 | B9: 6900.44 | C9: 6913.25 | D9: 6893.47 | E9: 6896.24 | F9: 6896.24 | G9: 3309930000
A10: 46020 | B10: 6903.6 | C10: 6920.21 | D10: 6888.76 | E10: 6905.74 | F10: 6905.74 | G10: 3541750000
A11: 46017 | B11: 6936.02 | C11: 6945.77 | D11: 6921.6 | E11: 6929.94 | F11: 6929.94 | G11: 2586550000
A12: 46015 | B12: 6904.91 | C12: 6937.32 | D12: 6904.91 | E12: 6932.05 | F12: 6932.05 | G12: 1798270000
A13: 46014 | B13: 6872.41 | C13: 6910.88 | D13: 6868.81 | E13: 6909.79 | F13: 6909.79 | G13: 3820560000
... A251: 45670 | B251: 5782.02 | C251: 5838.61 | D251: 5773.31 | E251: 5836.22 | F251: 5836.22 | G251: 4421200000

Sheet Prices
A1: Date | B1: NFLX_AdjClose | C1: V_AdjClose | D1: XOM_AdjClose | E1: PFE_AdjClose | F1: PG_AdjClose | G1: S&P 500_AdjClose
A2: 46031 | B2: 89.46 | C2: =INDEX(V!$F$2:$F$252,MATCH($A2,V!$A$2:$A$252,0)) -> 349.77 | D2: =INDEX(XOM!$F$2:$F$252,MATCH($A2,XOM!$A$2:$A$252,0)) -> 124.61 | E2: =INDEX(PFE!$F$2:$F$252,MATCH($A2,PFE!$A$2:$A$252,0)) -> 25.48 | F2: =INDEX(PG!$F$2:$F$252,MATCH($A2,PG!$A$2:$A$252,0)) -> 141.87 | G2: =INDEX('S&P 500'!$F$2:$F$251,MATCH($A2,'S&P 500'!$A$2:$A$251,0)) -> 6966.28
A3: 46030 | B3: 90.53 | C3: =INDEX(V!$F$2:$F$252,MATCH($A3,V!$A$2:$A$252,0)) -> 352.23 | D3: =INDEX(XOM!$F$2:$F$252,MATCH($A3,XOM!$A$2:$A$252,0)) -> 122.91 | E3: =INDEX(PFE!$F$2:$F$252,MATCH($A3,PFE!$A$2:$A$252,0)) -> 25.29 | F3: =INDEX(PG!$F$2:$F$252,MATCH($A3,PG!$A$2:$A$252,0)) -> 141.53 | G3: =INDEX('S&P 500'!$F$2:$F$251,MATCH($A3,'S&P 500'!$A$2:$A$251,0)) -> 6921.46
A4: 46029 | B4: 90.73 | C4: =INDEX(V!$F$2:$F$252,MATCH($A4,V!$A$2:$A$252,0)) -> 355.88 | D4: =INDEX(XOM!$F$2:$F$252,MATCH($A4,XOM!$A$2:$A$252,0)) -> 118.49 | E4: =INDEX(PFE!$F$2:$F$252,MATCH($A4,PFE!$A$2:$A$252,0)) -> 25.28 | F4: =INDEX(PG!$F$2:$F$252,MATCH($A4,PG!$A$2:$A$252,0)) -> 138.04 | G4: =INDEX('S&P 500'!$F$2:$F$251,MATCH($A4,'S&P 500'!$A$2:$A$251,0)) -> 6920.93
A5: 46028 | B5: 90.65 | C5: =INDEX(V!$F$2:$F$252,MATCH($A5,V!$A$2:$A$252,0)) -> 357.56 | D5: =INDEX(XOM!$F$2:$F$252,MATCH($A5,XOM!$A$2:$A$252,0)) -> 121.05 | E5: =INDEX(PFE!$F$2:$F$252,MATCH($A5,PFE!$A$2:$A$252,0)) -> 25.43 | F5: =INDEX(PG!$F$2:$F$252,MATCH($A5,PG!$A$2:$A$252,0)) -> 139.91 | G5: =INDEX('S&P 500'!$F$2:$F$251,MATCH($A5,'S&P 500'!$A$2:$A$251,0)) -> 6944.82
A6: 46027 | B6: 91.46 | C6: =INDEX(V!$F$2:$F$252,MATCH($A6,V!$A$2:$A$252,0)) -> 353.8 | D6: =INDEX(XOM!$F$2:$F$252,MATCH($A6,XOM!$A$2:$A$252,0)) -> 125.36 | E6: =INDEX(PFE!$F$2:$F$252,MATCH($A6,PFE!$A$2:$A$252,0)) -> 25.17 | F6: =INDEX(PG!$F$2:$F$252,MATCH($A6,PG!$A$2:$A$252,0)) -> 140.37 | G6: =INDEX('S&P 500'!$F$2:$F$251,MATCH($A6,'S&P 500'!$A$2:$A$251,0)) -> 6902.05
A7: 46024 | B7: 90.99 | C7: =INDEX(V!$F$2:$F$252,MATCH($A7,V!$A$2:$A$252,0)) -> 346.48 | D7: =INDEX(XOM!$F$2:$F$252,MATCH($A7,XOM!$A$2:$A$252,0)) -> 122.65 | E7: =INDEX(PFE!$F$2:$F$252,MATCH($A7,PFE!$A$2:$A$252,0)) -> 25.18 | F7: =INDEX(PG!$F$2:$F$252,MATCH($A7,PG!$A$2:$A$252,0)) -> 141.79 | G7: =INDEX('S&P 500'!$F$2:$F$251,MATCH($A7,'S&P 500'!$A$2:$A$251,0)) -> 6858.47
A8: 46022 | B8: 93.76 | C8: =INDEX(V!$F$2:$F$252,MATCH($A8,V!$A$2:$A$252,0)) -> 350.71 | D8: =INDEX(XOM!$F$2:$F$252,MATCH($A8,XOM!$A$2:$A$252,0)) -> 120.34 | E8: =INDEX(PFE!$F$2:$F$252,MATCH($A8,PFE!$A$2:$A$252,0)) -> 24.9 | F8: =INDEX(PG!$F$2:$F$252,MATCH($A8,PG!$A$2:$A$252,0)) -> 143.31 | G8: =INDEX('S&P 500'!$F$2:$F$251,MATCH($A8,'S&P 500'!$A$2:$A$251,0)) -> 6845.5
A9: 46021 | B9: 93.78 | C9: =INDEX(V!$F$2:$F$252,MATCH($A9,V!$A$2:$A$252,0)) -> 353.62 | D9: =INDEX(XOM!$F$2:$F$252,MATCH($A9,XOM!$A$2:$A$252,0)) -> 120.99 | E9: =INDEX(PFE!$F$2:$F$252,MATCH($A9,PFE!$A$2:$A$252,0)) -> 24.99 | F9: =INDEX(PG!$F$2:$F$252,MATCH($A9,PG!$A$2:$A$252,0)) -> 144.05 | G9: =INDEX('S&P 500'!$F$2:$F$251,MATCH($A9,'S&P 500'!$A$2:$A$251,0)) -> 6896.24
A10: 46020 | B10: 94.15 | C10: =INDEX(V!$F$2:$F$252,MATCH($A10,V!$A$2:$A$252,0)) -> 354.61 | D10: =INDEX(XOM!$F$2:$F$252,MATCH($A10,XOM!$A$2:$A$252,0)) -> 120.53 | E10: =INDEX(PFE!$F$2:$F$252,MATCH($A10,PFE!$A$2:$A$252,0)) -> 25 | F10: =INDEX(PG!$F$2:$F$252,MATCH($A10,PG!$A$2:$A$252,0)) -> 144.57 | G10: =INDEX('S&P 500'!$F$2:$F$251,MATCH($A10,'S&P 500'!$A$2:$A$251,0)) -> 6905.74
A11: 46017 | B11: 94.47 | C11: =INDEX(V!$F$2:$F$252,MATCH($A11,V!$A$2:$A$252,0)) -> 355 | D11: =INDEX(XOM!$F$2:$F$252,MATCH($A11,XOM!$A$2:$A$252,0)) -> 119.11 | E11: =INDEX(PFE!$F$2:$F$252,MATCH($A11,PFE!$A$2:$A$252,0)) -> 25.09 | F11: =INDEX(PG!$F$2:$F$252,MATCH($A11,PG!$A$2:$A$252,0)) -> 144.74 | G11: =INDEX('S&P 500'!$F$2:$F$251,MATCH($A11,'S&P 500'!$A$2:$A$251,0)) -> 6929.94
A12: 46015 | B12: 93.64 | C12: =INDEX(V!$F$2:$F$252,MATCH($A12,V!$A$2:$A$252,0)) -> 355.14 | D12: =INDEX(XOM!$F$2:$F$252,MATCH($A12,XOM!$A$2:$A$252,0)) -> 119.22 | E12: =INDEX(PFE!$F$2:$F$252,MATCH($A12,PFE!$A$2:$A$252,0)) -> 25.03 | F12: =INDEX(PG!$F$2:$F$252,MATCH($A12,PG!$A$2:$A$252,0)) -> 144.49 | G12: =INDEX('S&P 500'!$F$2:$F$251,MATCH($A12,'S&P 500'!$A$2:$A$251,0)) -> 6932.05
A13: 46014 | B13: 93.5 | C13: =INDEX(V!$F$2:$F$252,MATCH($A13,V!$A$2:$A$252,0)) -> 353.38 | D13: =INDEX(XOM!$F$2:$F$252,MATCH($A13,XOM!$A$2:$A$252,0)) -> 119.42 | E13: =INDEX(PFE!$F$2:$F$252,MATCH($A13,PFE!$A$2:$A$252,0)) -> 24.88 | F13: =INDEX(PG!$F$2:$F$252,MATCH($A13,PG!$A$2:$A$252,0)) -> 143.18 | G13: =INDEX('S&P 500'!$F$2:$F$251,MATCH($A13,'S&P 500'!$A$2:$A$251,0)) -> 6909.79
... A251: 45670 | B251: 84.03 | C251: =INDEX(V!$F$2:$F$252,MATCH($A251,V!$A$2:$A$252,0)) -> 304.76 | D251: =INDEX(XOM!$F$2:$F$252,MATCH($A251,XOM!$A$2:$A$252,0)) -> 105.42 | E251: =INDEX(PFE!$F$2:$F$252,MATCH($A251,PFE!$A$2:$A$252,0)) -> 24.99 | F251: =INDEX(PG!$F$2:$F$252,MATCH($A251,PG!$A$2:$A$252,0)) -> 154.75 | G251: =INDEX('S&P 500'!$F$2:$F$251,MATCH($A251,'S&P 500'!$A$2:$A$251,0)) -> 5836.22

Sheet Daily Returns
A1: Date | B1: NFLX_Return | C1: V_Return | D1: XOM_Return | E1: PFE_Return | F1: PG_Return | G1: S&P 500_Return
A2: 46031 | B2: =(Prices!B2/Prices!B3)-1 -> -0.011819286 | C2: =(Prices!C2/Prices!C3)-1 -> -0.0069840729 | D2: =(Prices!D2/Prices!D3)-1 -> 0.013831259 | E2: =(Prices!E2/Prices!E3)-1 -> 0.0075128509 | F2: =(Prices!F2/Prices!F3)-1 -> 0.0024023175 | G2: =(Prices!G2/Prices!G3)-1 -> 0.0064755124
A3: 46030 | B3: =(Prices!B3/Prices!B4)-1 -> -0.0022043426 | C3: =(Prices!C3/Prices!C4)-1 -> -0.010256266 | D3: =(Prices!D3/Prices!D4)-1 -> 0.037302726 | E3: =(Prices!E3/Prices!E4)-1 -> 0.00039556962 | F3: =(Prices!F3/Prices!F4)-1 -> 0.025282527 | G3: =(Prices!G3/Prices!G4)-1 -> 7.6579304e-05
A4: 46029 | B4: =(Prices!B4/Prices!B5)-1 -> 0.00088251517 | C4: =(Prices!C4/Prices!C5)-1 -> -0.0046985121 | D4: =(Prices!D4/Prices!D5)-1 -> -0.021148286 | E4: =(Prices!E4/Prices!E5)-1 -> -0.005898545 | F4: =(Prices!F4/Prices!F5)-1 -> -0.013365735 | G4: =(Prices!G4/Prices!G5)-1 -> -0.003439974
A5: 46028 | B5: =(Prices!B5/Prices!B6)-1 -> -0.0088563306 | C5: =(Prices!C5/Prices!C6)-1 -> 0.010627473 | D5: =(Prices!D5/Prices!D6)-1 -> -0.034380983 | E5: =(Prices!E5/Prices!E6)-1 -> 0.010329758 | F5: =(Prices!F5/Prices!F6)-1 -> -0.0032770535 | G5: =(Prices!G5/Prices!G6)-1 -> 0.0061967097
A6: 46027 | B6: =(Prices!B6/Prices!B7)-1 -> 0.0051654028 | C6: =(Prices!C6/Prices!C7)-1 -> 0.021126761 | D6: =(Prices!D6/Prices!D7)-1 -> 0.022095393 | E6: =(Prices!E6/Prices!E7)-1 -> -0.00039714059 | F6: =(Prices!F6/Prices!F7)-1 -> -0.010014811 | G6: =(Prices!G6/Prices!G7)-1 -> 0.0063541869
A7: 46024 | B7: =(Prices!B7/Prices!B8)-1 -> -0.029543515 | C7: =(Prices!C7/Prices!C8)-1 -> -0.012061247 | D7: =(Prices!D7/Prices!D8)-1 -> 0.019195612 | E7: =(Prices!E7/Prices!E8)-1 -> 0.01124498 | F7: =(Prices!F7/Prices!F8)-1 -> -0.010606378 | G7: =(Prices!G7/Prices!G8)-1 -> 0.0018946753
A8: 46022 | B8: =(Prices!B8/Prices!B9)-1 -> -0.00021326509 | C8: =(Prices!C8/Prices!C9)-1 -> -0.0082291726 | D8: =(Prices!D8/Prices!D9)-1 -> -0.0053723448 | E8: =(Prices!E8/Prices!E9)-1 -> -0.0036014406 | F8: =(Prices!F8/Prices!F9)-1 -> -0.0051371052 | G8: =(Prices!G8/Prices!G9)-1 -> -0.0073576326
A9: 46021 | B9: =(Prices!B9/Prices!B10)-1 -> -0.0039298991 | C9: =(Prices!C9/Prices!C10)-1 -> -0.0027917994 | D9: =(Prices!D9/Prices!D10)-1 -> 0.0038164772 | E9: =(Prices!E9/Prices!E10)-1 -> -0.0004 | F9: =(Prices!F9/Prices!F10)-1 -> -0.0035968735 | G9: =(Prices!G9/Prices!G10)-1 -> -0.0013756672
A10: 46020 | B10: =(Prices!B10/Prices!B11)-1 -> -0.0033873187 | C10: =(Prices!C10/Prices!C11)-1 -> -0.0010985915 | D10: =(Prices!D10/Prices!D11)-1 -> 0.011921753 | E10: =(Prices!E10/Prices!E11)-1 -> -0.0035870865 | F10: =(Prices!F10/Prices!F11)-1 -> -0.0011745198 | G10: =(Prices!G10/Prices!G11)-1 -> -0.0034920937
A11: 46017 | B11: =(Prices!B11/Prices!B12)-1 -> 0.0088637334 | C11: =(Prices!C11/Prices!C12)-1 -> -0.00039421073 | D11: =(Prices!D11/Prices!D12)-1 -> -0.00092266398 | E11: =(Prices!E11/Prices!E12)-1 -> 0.0023971235 | F11: =(Prices!F11/Prices!F12)-1 -> 0.0017302235 | G11: =(Prices!G11/Prices!G12)-1 -> -0.00030438326
A12: 46015 | B12: =(Prices!B12/Prices!B13)-1 -> 0.0014973262 | C12: =(Prices!C12/Prices!C13)-1 -> 0.0049804743 | D12: =(Prices!D12/Prices!D13)-1 -> -0.0016747613 | E12: =(Prices!E12/Prices!E13)-1 -> 0.0060289389 | F12: =(Prices!F12/Prices!F13)-1 -> 0.0091493225 | G12: =(Prices!G12/Prices!G13)-1 -> 0.0032215161
A13: 46014 | B13: =(Prices!B13/Prices!B14)-1 -> 0.0028960635 | C13: =(Prices!C13/Prices!C14)-1 -> 0.003663836 | D13: =(Prices!D13/Prices!D14)-1 -> 0.010749048 | E13: =(Prices!E13/Prices!E14)-1 -> -0.013090044 | F13: =(Prices!F13/Prices!F14)-1 -> 0.0034340178 | G13: =(Prices!G13/Prices!G14)-1 -> 0.0045504173
... A250: 45671 | B250: =(Prices!B250/Prices!B251)-1 -> -0.014161609 | C250: =(Prices!C250/Prices!C251)-1 -> 0.0070547316 | D250: =(Prices!D250/Prices!D251)-1 -> 0.0039840637 | E250: =(Prices!E250/Prices!E251)-1 -> -0.014405762 | F250: =(Prices!F250/Prices!F251)-1 -> 0.0056865913 | G250: =(Prices!G250/Prices!G251)-1 -> 0.0011462899
A251: 45670 | B251: =IFERROR((Prices!B251/Prices!B252)-1,"") | C251: =IFERROR((Prices!C251/Prices!C252)-1,"") | D251: =IFERROR((Prices!D251/Prices!D252)-1,"") | E251: =IFERROR((Prices!E251/Prices!E252)-1,"") | F251: =IFERROR((Prices!F251/Prices!F252)-1,"") | G251: =IFERROR((Prices!G251/Prices!G252)-1,"")

Sheet Task (I) Result
A1: Stock | B1: NFLX | C1: V | D1: XOM | E1: PFE | F1: PG
A2: Mean Daily Return | B2: =AVERAGE('Daily Returns'!B2:B251) -> 0.00047966736 | C2: =AVERAGE('Daily Returns'!C2:C251) -> 0.00065534246 | D2: =AVERAGE('Daily Returns'!D2:D251) -> 0.00078743657 | E2: =AVERAGE('Daily Returns'!E2:E251) -> 0.00021246794 | F2: =AVERAGE('Daily Returns'!F2:F251) -> -0.00027817399
A3: Annual Expected Return | B3: =AVERAGE('Daily Returns'!B2:B251)*252 -> 0.12087618 | C3: =AVERAGE('Daily Returns'!C2:C251)*252 -> 0.1651463 | D3: =AVERAGE('Daily Returns'!D2:D251)*252 -> 0.19843401 | E3: =AVERAGE('Daily Returns'!E2:E251)*252 -> 0.05354192 | F3: =AVERAGE('Daily Returns'!F2:F251)*252 -> -0.070099845
A4: Daily Volatility | B4: =_xlfn.STDEV.S('Daily Returns'!B2:B251) -> 0.021351179 | C4: =_xlfn.STDEV.S('Daily Returns'!C2:C251) -> 0.014297797 | D4: =_xlfn.STDEV.S('Daily Returns'!D2:D251) -> 0.015176196 | E4: =_xlfn.STDEV.S('Daily Returns'!E2:E251) -> 0.016459982 | F4: =_xlfn.STDEV.S('Daily Returns'!F2:F251) -> 0.011888645
A5: Annual Volatility | B5: =_xlfn.STDEV.S('Daily Returns'!B2:B251)*SQRT(252) -> 0.33893947 | C5: =_xlfn.STDEV.S('Daily Returns'!C2:C251)*SQRT(252) -> 0.22697048 | D5: =_xlfn.STDEV.S('Daily Returns'!D2:D251)*SQRT(252) -> 0.24091465 | E5: =_xlfn.STDEV.S('Daily Returns'!E2:E251)*SQRT(252) -> 0.26129412 | F5: =_xlfn.STDEV.S('Daily Returns'!F2:F251)*SQRT(252) -> 0.18872638
A7: Correlation Matrix
B9: NFLX_Return | C9: V_Return | D9: XOM_Return | E9: PFE_Return | F9: PG_Return
A10: NFLX_Return | B10: 1 | C10: 0.36310806 | D10: 0.076941454 | E10: -0.012200944 | F10: 0.035050355
A11: V_Return | B11: 0.36310806 | C11: 1 | D11: 0.28729348 | E11: 0.36227795 | F11: 0.37621044
A12: XOM_Return | B12: 0.076941454 | C12: 0.28729348 | D12: 1 | E12: 0.2422165 | F12: 0.22383376
A13: PFE_Return | B13: -0.012200944 | C13: 0.36227795 | D13: 0.2422165 | E13: 1 | F13: 0.34101943
A14: PG_Return | B14: 0.035050355 | C14: 0.37621044 | D14: 0.22383376 | E14: 0.34101943 | F14: 1

Sheet Task (II) Result
A1: Stock | B1: NFLX | C1: V | D1: XOM | E1: PFE | F1: PG
A2: Annual Expected Return | B2: =AVERAGE('Daily Returns'!B2:B251)*252 -> 0.12087618 | C2: =AVERAGE('Daily Returns'!C2:C251)*252 -> 0.1651463 | D2: =AVERAGE('Daily Returns'!D2:D251)*252 -> 0.19843401 | E2: =AVERAGE('Daily Returns'!E2:E251)*252 -> 0.05354192 | F2: =AVERAGE('Daily Returns'!F2:F251)*252 -> -0.070099845
A3: Annual Volatility | B3: =_xlfn.STDEV.S('Daily Returns'!B2:B251)*SQRT(252) -> 0.33893947 | C3: =_xlfn.STDEV.S('Daily Returns'!C2:C251)*SQRT(252) -> 0.22697048 | D3: =_xlfn.STDEV.S('Daily Returns'!D2:D251)*SQRT(252) -> 0.24091465 | E3: =_xlfn.STDEV.S('Daily Returns'!E2:E251)*SQRT(252) -> 0.26129412 | F3: =_xlfn.STDEV.S('Daily Returns'!F2:F251)*SQRT(252) -> 0.18872638
A5: Covariance Matrix (Annual) | H5: Covariance Matrix (Daily)
B7: NFLX_Return | C7: V_Return | D7: XOM_Return | E7: PFE_Return | F7: PG_Return | I7: NFLX_Return | J7: V_Return | K7: XOM_Return | L7: PFE_Return | M7: PG_Return
A8: NFLX_Return | B8: =I8*252 -> 0.11487996 | C8: =J8*252 -> 0.027933633 | D8: =K8*252 -> 0.0062826916 | E8: =L8*252 -> -0.0010805509 | F8: =M8*252 -> 0.0022420597 | H8: NFLX_Return | I8: =_xlfn.COVARIANCE.S('Daily Returns'!B2:B250, 'Daily Returns'!$B$2:$B$250) -> 0.00045587286 | J8: =_xlfn.COVARIANCE.S('Daily Returns'!C2:C250, 'Daily Returns'!$B$2:$B$250) -> 0.00011084775 | K8: =_xlfn.COVARIANCE.S('Daily Returns'!D2:D250, 'Daily Returns'!$B$2:$B$250) -> 2.4931316e-05 | L8: =_xlfn.COVARIANCE.S('Daily Returns'!E2:E250, 'Daily Returns'!$B$2:$B$250) -> -4.2879002e-06 | M8: =_xlfn.COVARIANCE.S('Daily Returns'!F2:F250, 'Daily Returns'!$B$2:$B$250) -> 8.8970623e-06
A9: V_Return | B9: =I9*252 -> 0.027933633 | C9: =J9*252 -> 0.051515601 | D9: =K9*252 -> 0.015709355 | E9: =L9*252 -> 0.021485275 | F9: =M9*252 -> 0.016115094 | H9: V_Return | I9: =_xlfn.COVARIANCE.S('Daily Returns'!B2:B250, 'Daily Returns'!$C$2:$C$250) -> 0.00011084775 | J9: =_xlfn.COVARIANCE.S('Daily Returns'!C2:C250, 'Daily Returns'!$C$2:$C$250) -> 0.00020442699 | K9: =_xlfn.COVARIANCE.S('Daily Returns'!D2:D250, 'Daily Returns'!$C$2:$C$250) -> 6.2338711e-05 | L9: =_xlfn.COVARIANCE.S('Daily Returns'!E2:E250, 'Daily Returns'!$C$2:$C$250) -> 8.5259026e-05 | M9: =_xlfn.COVARIANCE.S('Daily Returns'!F2:F250, 'Daily Returns'!$C$2:$C$250) -> 6.3948786e-05
A10: XOM_Return | B10: =I10*252 -> 0.0062826916 | C10: =J10*252 -> 0.015709355 | D10: =K10*252 -> 0.058039869 | E10: =L10*252 -> 0.015247427 | F10: =M10*252 -> 0.010177038 | H10: XOM_Return | I10: =_xlfn.COVARIANCE.S('Daily Returns'!B2:B250, 'Daily Returns'!$D$2:$D$250) -> 2.4931316e-05 | J10: =_xlfn.COVARIANCE.S('Daily Returns'!C2:C250, 'Daily Returns'!$D$2:$D$250) -> 6.2338711e-05 | K10: =_xlfn.COVARIANCE.S('Daily Returns'!D2:D250, 'Daily Returns'!$D$2:$D$250) -> 0.00023031694 | L10: =_xlfn.COVARIANCE.S('Daily Returns'!E2:E250, 'Daily Returns'!$D$2:$D$250) -> 6.0505662e-05 | M10: =_xlfn.COVARIANCE.S('Daily Returns'!F2:F250, 'Daily Returns'!$D$2:$D$250) -> 4.0385073e-05
A11: PFE_Return | B11: =I11*252 -> -0.0010805509 | C11: =J11*252 -> 0.021485275 | D11: =K11*252 -> 0.015247427 | E11: =L11*252 -> 0.068274615 | F11: =M11*252 -> 0.016816723 | H11: PFE_Return | I11: =_xlfn.COVARIANCE.S('Daily Returns'!B2:B250, 'Daily Returns'!$E$2:$E$250) -> -4.2879002e-06 | J11: =_xlfn.COVARIANCE.S('Daily Returns'!C2:C250, 'Daily Returns'!$E$2:$E$250) -> 8.5259026e-05 | K11: =_xlfn.COVARIANCE.S('Daily Returns'!D2:D250, 'Daily Returns'!$E$2:$E$250) -> 6.0505662e-05 | L11: =_xlfn.COVARIANCE.S('Daily Returns'!E2:E250, 'Daily Returns'!$E$2:$E$250) -> 0.00027093101 | M11: =_xlfn.COVARIANCE.S('Daily Returns'!F2:F250, 'Daily Returns'!$E$2:$E$250) -> 6.6733027e-05
A12: PG_Return | B12: =I12*252 -> 0.0022420597 | C12: =J12*252 -> 0.016115094 | D12: =K12*252 -> 0.010177038 | E12: =L12*252 -> 0.016816723 | F12: =M12*252 -> 0.035617647 | H12: PG_Return | I12: =_xlfn.COVARIANCE.S('Daily Returns'!B2:B250, 'Daily Returns'!$F$2:$F$250) -> 8.8970623e-06 | J12: =_xlfn.COVARIANCE.S('Daily Returns'!C2:C250, 'Daily Returns'!$F$2:$F$250) -> 6.3948786e-05 | K12: =_xlfn.COVARIANCE.S('Daily Returns'!D2:D250, 'Daily Returns'!$F$2:$F$250) -> 4.0385073e-05 | L12: =_xlfn.COVARIANCE.S('Daily Returns'!E2:E250, 'Daily Returns'!$F$2:$F$250) -> 6.6733027e-05 | M12: =_xlfn.COVARIANCE.S('Daily Returns'!F2:F250, 'Daily Returns'!$F$2:$F$250) -> 0.00014133987
A14: Decision Variables
A16: Stock | B16: NFLX | C16: V | D16: XOM | E16: PFE | F16: PG | G16: Total Weight | H16: Target Return (%) | I16: Portfolio volatility (risk)
A17: Portfolio Weight 1 | B17: 0.16216088 | C17: 0.1877263 | D17: 0.17849743 | E17: 0.21866813 | F17: 0.25294726 | G17: =SUM(B17:F17) -> 1 | H17: 0.08 | I17: =SQRT(B25) -> 0.15072347
A18: Portfolio Weight 2 | B18: 0.21789004 | C18: 0.20580291 | D18: 0.21016624 | E18: 0.19117386 | F18: 0.17496695 | G18: =SUM(B18:F18) -> 1 | H18: 0.1 | I18: =SQRT(C25) -> 0.15574227
A19: Portfolio Weight 3 | B19: 0.27361894 | C19: 0.22387942 | D19: 0.24183491 | E19: 0.16367972 | F19: 0.096987009 | G19: =SUM(B19:F19) -> 1 | H19: 0.12 | I19: =SQRT(D25) -> 0.16495857
A20: Portfolio Weight 4 | B20: 0.32060435 | C20: 0.2645002 | D20: 0.31299939 | E20: 0.10189605 | F20: 0 | G20: =SUM(B20:F20) -> 1 | H20: 0.15 | I20: =SQRT(E25) -> 0.18018567
A21: Portfolio Weight 5 | B21: 0.069027853 | C21: 0.39294585 | D21: 0.53802629 | E21: 0 | F21: 0 | G21: =SUM(B21:F21) -> 1 | H21: 0.18 | I21: =SQRT(F25) -> 0.18419303
A24: Portfolio expected return | B24: =SUMPRODUCT(B17:F17,$B$2:$F$2) -> 0.08 | C24: =SUMPRODUCT(B18:F18,$B$2:$F$2) -> 0.10000009 | D24: =SUMPRODUCT(B19:F19,$B$2:$F$2) -> 0.12000009 | E24: =SUMPRODUCT(B20:F20,$B$2:$F$2) -> 0.15000009 | F24: =SUMPRODUCT(B21:F21,$B$2:$F$2) -> 0.18000009
A25: Portfolio variance | B25: {=MMULT(MMULT(B17:F17, $B$8:$F$12), TRANSPOSE(B17:F17))} -> 0.022717564 | C25: {=MMULT(MMULT(B18:F18, $B$8:$F$12), TRANSPOSE(B18:F18))} -> 0.024255656 | D25: {=MMULT(MMULT(B19:F19, $B$8:$F$12), TRANSPOSE(B19:F19))} -> 0.027211331 | E25: {=MMULT(MMULT(B20:F20, $B$8:$F$12), TRANSPOSE(B20:F20))} -> 0.032466876 | F25: {=MMULT(MMULT(B21:F21, $B$8:$F$12), TRANSPOSE(B21:F21))} -> 0.033927071

Sheet Task (III) Result
A1: Portfolio | B1: Target Return (Rp) | C1: Portfolio Volatility (σp) | D1: Sharpe Ratio | E1: Capital Market Line
A2: 1 | B2: 0.08 | C2: 0.15072347 | D2: =(B2-$B$8)/C2 -> 0.43125334 | E2: =$B$8+$B$9*C2 -> 0.15001799
A3: 2 | B3: 0.1 | C3: 0.15574227 | D3: =(B3-$B$8)/C3 -> 0.54577347 | E3: =$B$8+$B$9*C3 -> 0.15451383
A4: 3 | B4: 0.12 | C4: 0.16495857 | D4: =(B4-$B$8)/C4 -> 0.63652345 | E4: =$B$8+$B$9*C4 -> 0.16276979
A5: 4 | B5: 0.15 | C5: 0.18018567 | D5: =(B5-$B$8)/C5 -> 0.74922717 | E5: =$B$8+$B$9*C5 -> 0.17641021
A6: 5 | B6: 0.18 | C6: 0.18419303 | D6: =(B6-$B$8)/C6 -> 0.89579938 | E6: =$B$8+$B$9*C6 -> 0.18
A8: Risk-free rate (Rf) | B8: 0.015
A9: Tangency Portfolio | B9: =MAX(D2:D6) -> 0.89579938

Sheet Task (IV) Result
A1: PART A: BETA USING LINEAR REGRESSION
A3: SUMMARY OUTPUT FOR NFLX_Return Vs S&P500_Return
A5: Regression Statistics
A6: Multiple R | B6: 0.46205894
A7: R Square | B7: 0.21349847
A8: Adjusted R Square | B8: 0.21031425
A9: Standard Error | B9: 0.018973569
A10: Observations | B10: 249
A12: ANOVA
B13: df | C13: SS | D13: MS | E13: F | F13: Significance F
A14: Regression | B14: 1 | C14: 0.024137383 | D14: 0.024137383 | E14: 67.048975 | F14: 1.4228094e-14
A15: Residual | B15: 247 | C15: 0.088919087 | D15: 0.0003599963
A16: Total | B16: 248 | C16: 0.11305647
B18: Coefficients | C18: Standard Error | D18: t Stat | E18: P-value | F18: Lower 95% | G18: Upper 95% | H18: Lower 95.0% | I18: Upper 95.0%
A19: Intercept | B19: -0.00017428581 | C19: 0.0012050504 | D19: -0.14462947 | E19: 0.88512137 | F19: -0.0025477709 | G19: 0.0021991993 | H19: -0.0025477709 | I19: 0.0021991993
A20: S&P 500_Return | B20: 0.83903787 | C20: 0.10246735 | D20: 8.1883438 | E20: 1.4228094e-14 | F20: 0.63721667 | G20: 1.0408591 | H20: 0.63721667 | I20: 1.0408591
A24: SUMMARY OUTPUT FOR V_Return Vs S&P500_Return
A26: Regression Statistics
A27: Multiple R | B27: 0.64648611
A28: R Square | B28: 0.41794429
A29: Adjusted R Square | B29: 0.41558779
A30: Standard Error | B30: 0.010930216
A31: Observations | B31: 249
A33: ANOVA
B34: df | C34: SS | D34: MS | E34: F | F34: Significance F
A35: Regression | B35: 1 | C35: 0.021188895 | D35: 0.021188895 | E35: 177.358 | F35: 7.3336347e-31
A36: Residual | B36: 247 | C36: 0.029508998 | D36: 0.00011946963
A37: Total | B37: 248 | C37: 0.050697893
B39: Coefficients | C39: Standard Error | D39: t Stat | E39: P-value | F39: Lower 95% | G39: Upper 95% | H39: Lower 95.0% | I39: Upper 95.0%
A40: Intercept | B40: 4.2631412e-05 | C40: 0.00069420055 | D40: 0.061410801 | E40: 0.95108171 | F40: -0.0013246762 | G40: 0.0014099391 | H40: -0.0013246762 | I40: 0.0014099391
A41: S&P 500_Return | B41: 0.78612321 | C41: 0.059028973 | D41: 13.317582 | E41: 7.3336347e-31 | F41: 0.66985888 | G41: 0.90238755 | H41: 0.66985888 | I41: 0.90238755
A45: SUMMARY OUTPUT FOR XOM_Return Vs S&P500_Return
A47: Regression Statistics
A48: Multiple R | B48: 0.41269528
A49: R Square | B49: 0.17031739
A50: Adjusted R Square | B50: 0.16695835
A51: Standard Error | B51: 0.013851484
A52: Observations | B52: 249
A54: ANOVA
B55: df | C55: SS | D55: MS | E55: F | F55: Significance F
...
